import {
  throwError,
  throwCustomError,
  resolveValue,
  MyAwesomeError,
  rejectCustomError,
} from './index';

describe('resolveValue', () => {
  test('should resolve provided value', async () => {
    const value = 'value';
    const result = await resolveValue(value);
    expect(result).toBe(value);
  });
});

describe('throwError', () => {
  test('should throw error with provided message', () => {
    const message = 'This is error';
    expect(() => throwError(message)).toThrow(message);
  });

  test('should throw error with default message if message is not provided', () => {
    const defaultMessage = 'Oops!';
    expect(() => throwError()).toThrow(defaultMessage);
  });
});

describe('throwCustomError', () => {
  test('should throw custom error', () => {
    expect(() => throwCustomError()).toThrow(MyAwesomeError);
    expect(() => throwCustomError()).toThrow(
      'This is my awesome custom error!',
    );
  });
});

describe('rejectCustomError', () => {
  test('should reject custom error', async () => {
    const errorMessage = 'This is my awesome custom error!';
    await expect(rejectCustomError()).rejects.toThrow(MyAwesomeError);
    await expect(rejectCustomError()).rejects.toThrow(errorMessage);
  });
});
